[2023-05-31 09:25:07] ERROR: Exception on /local_excel [GET]
Traceback (most recent call last):
  File "C:\Users\meer0084\ownCloud - J.M. van der Meer@hzresearchdrive.data.surfsara.nl2\2562 ZET\WP1\transport_kompas\excel_interfaces\AbstractExcelInterface.py", line 27, in __init__
    self.excel_model = ExcelCompiler(filename=path_to_excel)
  File "C:\Users\meer0084\AppData\Local\anaconda3\envs\kompas\lib\site-packages\pycel\excelcompiler.py", line 73, in __init__
    self.excel.load()
  File "C:\Users\meer0084\AppData\Local\anaconda3\envs\kompas\lib\site-packages\pycel\excelwrapper.py", line 243, in load
    self.workbook = load_workbook(self.filename)
  File "C:\Users\meer0084\AppData\Local\anaconda3\envs\kompas\lib\site-packages\openpyxl\reader\excel.py", line 315, in load_workbook
    reader = ExcelReader(filename, read_only, keep_vba,
  File "C:\Users\meer0084\AppData\Local\anaconda3\envs\kompas\lib\site-packages\openpyxl\reader\excel.py", line 124, in __init__
    self.archive = _validate_archive(fn)
  File "C:\Users\meer0084\AppData\Local\anaconda3\envs\kompas\lib\site-packages\openpyxl\reader\excel.py", line 96, in _validate_archive
    archive = ZipFile(filename, 'r')
  File "C:\Users\meer0084\AppData\Local\anaconda3\envs\kompas\lib\zipfile.py", line 1251, in __init__
    self.fp = io.open(file, filemode)
FileNotFoundError: [Errno 2] No such file or directory: 'C:\\Users\\meer0084\\ownCloud - J.M. van der Meer@hzresearchdrive.data.surfsara.nl2\\2562 ZET\\WP1\\40 Bedrijven\\Traveo\\Templates.xlsm'

During handling of the above exception, another exception occurred:

Traceback (most recent call last):
  File "C:\Users\meer0084\ownCloud - J.M. van der Meer@hzresearchdrive.data.surfsara.nl2\2562 ZET\WP1\transport_kompas\excel_interfaces\FleetInterface.py", line 27, in __init__
    super().__init__(path_to_fleet_data)
  File "C:\Users\meer0084\ownCloud - J.M. van der Meer@hzresearchdrive.data.surfsara.nl2\2562 ZET\WP1\transport_kompas\excel_interfaces\AbstractExcelInterface.py", line 29, in __init__
    raise NoExcelFileFound
exceptions.NoExcelFileFound: The specified excel file couldn't be found. Please check the path to the file.

During handling of the above exception, another exception occurred:

Traceback (most recent call last):
  File "C:\Users\meer0084\AppData\Local\anaconda3\envs\kompas\lib\site-packages\flask\app.py", line 2070, in wsgi_app
    response = self.full_dispatch_request()
  File "C:\Users\meer0084\AppData\Local\anaconda3\envs\kompas\lib\site-packages\flask\app.py", line 1515, in full_dispatch_request
    rv = self.handle_user_exception(e)
  File "C:\Users\meer0084\AppData\Local\anaconda3\envs\kompas\lib\site-packages\flask\app.py", line 1513, in full_dispatch_request
    rv = self.dispatch_request()
  File "C:\Users\meer0084\AppData\Local\anaconda3\envs\kompas\lib\site-packages\flask\app.py", line 1499, in dispatch_request
    return self.ensure_sync(self.view_functions[rule.endpoint])(**req.view_args)
  File "C:\Users\meer0084\ownCloud - J.M. van der Meer@hzresearchdrive.data.surfsara.nl2\2562 ZET\WP1\transport_kompas\app.py", line 39, in process_local_excel
    fleet_data = get_fleet_data_from_parameters(request, company)
  File "C:\Users\meer0084\ownCloud - J.M. van der Meer@hzresearchdrive.data.surfsara.nl2\2562 ZET\WP1\transport_kompas\request_functions.py", line 145, in get_fleet_data_from_parameters
    fleet_interface = FleetInterface(company, path_to_fleet_data)
  File "C:\Users\meer0084\ownCloud - J.M. van der Meer@hzresearchdrive.data.surfsara.nl2\2562 ZET\WP1\transport_kompas\excel_interfaces\FleetInterface.py", line 29, in __init__
    raise NoFleetDataFound
exceptions.NoFleetDataFound: The fleet data couldn't be found. Please check the path to the fleet data.
[2023-05-31 09:25:54] ERROR: Exception on /local_excel [GET]
Traceback (most recent call last):
  File "C:\Users\meer0084\AppData\Local\anaconda3\envs\kompas\lib\site-packages\flask\app.py", line 2070, in wsgi_app
    response = self.full_dispatch_request()
  File "C:\Users\meer0084\AppData\Local\anaconda3\envs\kompas\lib\site-packages\flask\app.py", line 1515, in full_dispatch_request
    rv = self.handle_user_exception(e)
  File "C:\Users\meer0084\AppData\Local\anaconda3\envs\kompas\lib\site-packages\flask\app.py", line 1513, in full_dispatch_request
    rv = self.dispatch_request()
  File "C:\Users\meer0084\AppData\Local\anaconda3\envs\kompas\lib\site-packages\flask\app.py", line 1499, in dispatch_request
    return self.ensure_sync(self.view_functions[rule.endpoint])(**req.view_args)
  File "C:\Users\meer0084\ownCloud - J.M. van der Meer@hzresearchdrive.data.surfsara.nl2\2562 ZET\WP1\transport_kompas\app.py", line 39, in process_local_excel
    fleet_data = get_fleet_data_from_parameters(request, company)
  File "C:\Users\meer0084\ownCloud - J.M. van der Meer@hzresearchdrive.data.surfsara.nl2\2562 ZET\WP1\transport_kompas\request_functions.py", line 145, in get_fleet_data_from_parameters
    fleet_interface = FleetInterface(company, path_to_fleet_data)
  File "C:\Users\meer0084\ownCloud - J.M. van der Meer@hzresearchdrive.data.surfsara.nl2\2562 ZET\WP1\transport_kompas\excel_interfaces\FleetInterface.py", line 50, in __init__
    is_cooled = convert_dutch_string_to_boolean(self.get_cell_value(company, f"F{index}"))
  File "C:\Users\meer0084\ownCloud - J.M. van der Meer@hzresearchdrive.data.surfsara.nl2\2562 ZET\WP1\transport_kompas\utility_functions.py", line 17, in convert_dutch_string_to_boolean
    if string.lower() == "ja":
AttributeError: 'NoneType' object has no attribute 'lower'
